Workbook

Sheet 00 Overview
A1: Legal V1 — UAT Business Test Cases
A2: Version 1.0 | B2: Generated 2026-07-03
A4: Sheet | B4: Module | C4: Total cases | D4: Passed | E4: Failed | F4: Blocked | G4: Not Run | H4: Pass %
A5: 01 Dashboard | B5: Dashboard | C5: 6 | D5: =COUNTIF('01 Dashboard'!I:I,"Passed") | E5: =COUNTIF('01 Dashboard'!I:I,"Failed") | F5: =COUNTIF('01 Dashboard'!I:I,"Blocked") | G5: =COUNTIF('01 Dashboard'!I:I,"Not Run") | H5: =IFERROR(D5/C5,0)
A6: 02 Compliance Referral | B6: Compliance Referral | C6: 12 | D6: =COUNTIF('02 Compliance Referral'!I:I,"Passed") | E6: =COUNTIF('02 Compliance Referral'!I:I,"Failed") | F6: =COUNTIF('02 Compliance Referral'!I:I,"Blocked") | G6: =COUNTIF('02 Compliance Referral'!I:I,"Not Run") | H6: =IFERROR(D6/C6,0)
A7: 03 Benefit Referral | B7: Benefit Referral | C7: 4 | D7: =COUNTIF('03 Benefit Referral'!I:I,"Passed") | E7: =COUNTIF('03 Benefit Referral'!I:I,"Failed") | F7: =COUNTIF('03 Benefit Referral'!I:I,"Blocked") | G7: =COUNTIF('03 Benefit Referral'!I:I,"Not Run") | H7: =IFERROR(D7/C7,0)
A8: 04 Intake | B8: Legal Intake | C8: 10 | D8: =COUNTIF('04 Intake'!I:I,"Passed") | E8: =COUNTIF('04 Intake'!I:I,"Failed") | F8: =COUNTIF('04 Intake'!I:I,"Blocked") | G8: =COUNTIF('04 Intake'!I:I,"Not Run") | H8: =IFERROR(D8/C8,0)
A9: 05 Legal Matter | B9: Matter Workspace | C9: 14 | D9: =COUNTIF('05 Legal Matter'!I:I,"Passed") | E9: =COUNTIF('05 Legal Matter'!I:I,"Failed") | F9: =COUNTIF('05 Legal Matter'!I:I,"Blocked") | G9: =COUNTIF('05 Legal Matter'!I:I,"Not Run") | H9: =IFERROR(D9/C9,0)
A10: 06 Hearings | B10: Court Operations | C10: 10 | D10: =COUNTIF('06 Hearings'!I:I,"Passed") | E10: =COUNTIF('06 Hearings'!I:I,"Failed") | F10: =COUNTIF('06 Hearings'!I:I,"Blocked") | G10: =COUNTIF('06 Hearings'!I:I,"Not Run") | H10: =IFERROR(D10/C10,0)
A11: 07 Orders | B11: Judicial Orders | C11: 8 | D11: =COUNTIF('07 Orders'!I:I,"Passed") | E11: =COUNTIF('07 Orders'!I:I,"Failed") | F11: =COUNTIF('07 Orders'!I:I,"Blocked") | G11: =COUNTIF('07 Orders'!I:I,"Not Run") | H11: =IFERROR(D11/C11,0)
A12: 08 Appeals | B12: Appeals | C12: 6 | D12: =COUNTIF('08 Appeals'!I:I,"Passed") | E12: =COUNTIF('08 Appeals'!I:I,"Failed") | F12: =COUNTIF('08 Appeals'!I:I,"Blocked") | G12: =COUNTIF('08 Appeals'!I:I,"Not Run") | H12: =IFERROR(D12/C12,0)
A13: 09 Enforcement | B13: Enforcement | C13: 8 | D13: =COUNTIF('09 Enforcement'!I:I,"Passed") | E13: =COUNTIF('09 Enforcement'!I:I,"Failed") | F13: =COUNTIF('09 Enforcement'!I:I,"Blocked") | G13: =COUNTIF('09 Enforcement'!I:I,"Not Run") | H13: =IFERROR(D13/C13,0)
A14: 10 Consent Orders | B14: Consent Orders | C14: 6 | D14: =COUNTIF('10 Consent Orders'!I:I,"Passed") | E14: =COUNTIF('10 Consent Orders'!I:I,"Failed") | F14: =COUNTIF('10 Consent Orders'!I:I,"Blocked") | G14: =COUNTIF('10 Consent Orders'!I:I,"Not Run") | H14: =IFERROR(D14/C14,0)
A15: 11 Recovery Assignment | B15: Recovery Assignment | C15: 8 | D15: =COUNTIF('11 Recovery Assignment'!I:I,"Passed") | E15: =COUNTIF('11 Recovery Assignment'!I:I,"Failed") | F15: =COUNTIF('11 Recovery Assignment'!I:I,"Blocked") | G15: =COUNTIF('11 Recovery Assignment'!I:I,"Not Run") | H15: =IFERROR(D15/C15,0)
A16: 12 Recoverable Liabilities | B16: Liabilities | C16: 12 | D16: =COUNTIF('12 Recoverable Liabilities'!I:I,"Passed") | E16: =COUNTIF('12 Recoverable Liabilities'!I:I,"Failed") | F16: =COUNTIF('12 Recoverable Liabilities'!I:I,"Blocked") | G16: =COUNTIF('12 Recoverable Liabilities'!I:I,"Not Run") | H16: =IFERROR(D16/C16,0)
A17: 13 External Counsel | B17: External Counsel | C17: 5 | D17: =COUNTIF('13 External Counsel'!I:I,"Passed") | E17: =COUNTIF('13 External Counsel'!I:I,"Failed") | F17: =COUNTIF('13 External Counsel'!I:I,"Blocked") | G17: =COUNTIF('13 External Counsel'!I:I,"Not Run") | H17: =IFERROR(D17/C17,0)
A18: 14 Court Filing | B18: Court Filing | C18: 5 | D18: =COUNTIF('14 Court Filing'!I:I,"Passed") | E18: =COUNTIF('14 Court Filing'!I:I,"Failed") | F18: =COUNTIF('14 Court Filing'!I:I,"Blocked") | G18: =COUNTIF('14 Court Filing'!I:I,"Not Run") | H18: =IFERROR(D18/C18,0)
A19: 15 Legal Cost | B19: Legal Cost | C19: 5 | D19: =COUNTIF('15 Legal Cost'!I:I,"Passed") | E19: =COUNTIF('15 Legal Cost'!I:I,"Failed") | F19: =COUNTIF('15 Legal Cost'!I:I,"Blocked") | G19: =COUNTIF('15 Legal Cost'!I:I,"Not Run") | H19: =IFERROR(D19/C19,0)
A20: 16 Reporting | B20: Reports & Dashboards | C20: 8 | D20: =COUNTIF('16 Reporting'!I:I,"Passed") | E20: =COUNTIF('16 Reporting'!I:I,"Failed") | F20: =COUNTIF('16 Reporting'!I:I,"Blocked") | G20: =COUNTIF('16 Reporting'!I:I,"Not Run") | H20: =IFERROR(D20/C20,0)
A21: 17 Security | B21: Security & Permissions | C21: 12 | D21: =COUNTIF('17 Security'!I:I,"Passed") | E21: =COUNTIF('17 Security'!I:I,"Failed") | F21: =COUNTIF('17 Security'!I:I,"Blocked") | G21: =COUNTIF('17 Security'!I:I,"Not Run") | H21: =IFERROR(D21/C21,0)
A22: 18 Negative Testing | B22: Negative | C22: 18 | D22: =COUNTIF('18 Negative Testing'!I:I,"Passed") | E22: =COUNTIF('18 Negative Testing'!I:I,"Failed") | F22: =COUNTIF('18 Negative Testing'!I:I,"Blocked") | G22: =COUNTIF('18 Negative Testing'!I:I,"Not Run") | H22: =IFERROR(D22/C22,0)
A23: 19 Financial Validation | B23: Financial | C23: 15 | D23: =COUNTIF('19 Financial Validation'!I:I,"Passed") | E23: =COUNTIF('19 Financial Validation'!I:I,"Failed") | F23: =COUNTIF('19 Financial Validation'!I:I,"Blocked") | G23: =COUNTIF('19 Financial Validation'!I:I,"Not Run") | H23: =IFERROR(D23/C23,0)
A24: 20 Production Signoff | B24: Signoff | C24: 6 | D24: =COUNTIF('20 Production Signoff'!I:I,"Passed") | E24: =COUNTIF('20 Production Signoff'!I:I,"Failed") | F24: =COUNTIF('20 Production Signoff'!I:I,"Blocked") | G24: =COUNTIF('20 Production Signoff'!I:I,"Not Run") | H24: =IFERROR(D24/C24,0)
A26: TOTAL | C26: 178 | D26: =SUM(D5:D23) | E26: =SUM(E5:E23) | F26: =SUM(F5:F23) | G26: =SUM(G5:G23) | H26: =IFERROR(D25/C25,0)

Sheet 01 Dashboard
A1: Test ID | B1: Module | C1: Business Requirement | D1: Scenario | E1: Pre-condition | F1: Steps | G1: Expected Result | H1: Actual Result | I1: Status | J1: Priority | K1: Severity | L1: Evidence Link | M1: Tester | N1: Date | O1: Comments | P1: Pass %
A2: DSH-001 | B2: Dashboard | C2: Dashboard — business requirement #1 | D2: Verify dashboard scenario 1 using seeded test data | E2: User logged in with required role; seeded records visible | F2: 1. Navigate to relevant workbench 2. Locate seeded record 3. Execute action 1 4. Verify result on screen and in view | G2: Result matches business expectation and reconciles with v_lg_case_financials where applicable | I2: Not Run | J2: High | P2: 0
A3: DSH-002 | B3: Dashboard | C3: Dashboard — business requirement #2 | D3: Verify dashboard scenario 2 using seeded test data | E3: User logged in with required role; seeded records visible | F3: 1. Navigate to relevant workbench 2. Locate seeded record 3. Execute action 2 4. Verify result on screen and in view | G3: Result matches business expectation and reconciles with v_lg_case_financials where applicable | I3: Not Run | J3: Medium | P3: 0
A4: DSH-003 | B4: Dashboard | C4: Dashboard — business requirement #3 | D4: Verify dashboard scenario 3 using seeded test data | E4: User logged in with required role; seeded records visible | F4: 1. Navigate to relevant workbench 2. Locate seeded record 3. Execute action 3 4. Verify result on screen and in view | G4: Result matches business expectation and reconciles with v_lg_case_financials where applicable | I4: Not Run | J4: Medium | P4: 0
A5: DSH-004 | B5: Dashboard | C5: Dashboard — business requirement #4 | D5: Verify dashboard scenario 4 using seeded test data | E5: User logged in with required role; seeded records visible | F5: 1. Navigate to relevant workbench 2. Locate seeded record 3. Execute action 4 4. Verify result on screen and in view | G5: Result matches business expectation and reconciles with v_lg_case_financials where applicable | I5: Not Run | J5: Low | P5: 0
A6: DSH-005 | B6: Dashboard | C6: Dashboard — business requirement #5 | D6: Verify dashboard scenario 5 using seeded test data | E6: User logged in with required role; seeded records visible | F6: 1. Navigate to relevant workbench 2. Locate seeded record 3. Execute action 5 4. Verify result on screen and in view | G6: Result matches business expectation and reconciles with v_lg_case_financials where applicable | I6: Not Run | J6: High | P6: 0
A7: DSH-006 | B7: Dashboard | C7: Dashboard — business requirement #6 | D7: Verify dashboard scenario 6 using seeded test data | E7: User logged in with required role; seeded records visible | F7: 1. Navigate to relevant workbench 2. Locate seeded record 3. Execute action 6 4. Verify result on screen and in view | G7: Result matches business expectation and reconciles with v_lg_case_financials where applicable | I7: Not Run | J7: High | P7: 0

Sheet 02 Compliance Referral
A1: Test ID | B1: Module | C1: Business Requirement | D1: Scenario | E1: Pre-condition | F1: Steps | G1: Expected Result | H1: Actual Result | I1: Status | J1: Priority | K1: Severity | L1: Evidence Link | M1: Tester | N1: Date | O1: Comments | P1: Pass %
A2: CRF-001 | B2: Compliance Referral | C2: Compliance Referral — business requirement #1 | D2: Verify compliance referral scenario 1 using seeded test data | E2: User logged in with required role; seeded records visible | F2: 1. Navigate to relevant workbench 2. Locate seeded record 3. Execute action 1 4. Verify result on screen and in view | G2: Result matches business expectation and reconciles with v_lg_case_financials where applicable | I2: Not Run | J2: High | P2: 0
A3: CRF-002 | B3: Compliance Referral | C3: Compliance Referral — business requirement #2 | D3: Verify compliance referral scenario 2 using seeded test data | E3: User logged in with required role; seeded records visible | F3: 1. Navigate to relevant workbench 2. Locate seeded record 3. Execute action 2 4. Verify result on screen and in view | G3: Result matches business expectation and reconciles with v_lg_case_financials where applicable | I3: Not Run | J3: Medium | P3: 0
A4: CRF-003 | B4: Compliance Referral | C4: Compliance Referral — business requirement #3 | D4: Verify compliance referral scenario 3 using seeded test data | E4: User logged in with required role; seeded records visible | F4: 1. Navigate to relevant workbench 2. Locate seeded record 3. Execute action 3 4. Verify result on screen and in view | G4: Result matches business expectation and reconciles with v_lg_case_financials where applicable | I4: Not Run | J4: Medium | P4: 0
A5: CRF-004 | B5: Compliance Referral | C5: Compliance Referral — business requirement #4 | D5: Verify compliance referral scenario 4 using seeded test data | E5: User logged in with required role; seeded records visible | F5: 1. Navigate to relevant workbench 2. Locate seeded record 3. Execute action 4 4. Verify result on screen and in view | G5: Result matches business expectation and reconciles with v_lg_case_financials where applicable | I5: Not Run | J5: Low | P5: 0
A6: CRF-005 | B6: Compliance Referral | C6: Compliance Referral — business requirement #5 | D6: Verify compliance referral scenario 5 using seeded test data | E6: User logged in with required role; seeded records visible | F6: 1. Navigate to relevant workbench 2. Locate seeded record 3. Execute action 5 4. Verify result on screen and in view | G6: Result matches business expectation and reconciles with v_lg_case_financials where applicable | I6: Not Run | J6: High | P6: 0
A7: CRF-006 | B7: Compliance Referral | C7: Compliance Referral — business requirement #6 | D7: Verify compliance referral scenario 6 using seeded test data | E7: User logged in with required role; seeded records visible | F7: 1. Navigate to relevant workbench 2. Locate seeded record 3. Execute action 6 4. Verify result on screen and in view | G7: Result matches business expectation and reconciles with v_lg_case_financials where applicable | I7: Not Run | J7: High | P7: 0
A8: CRF-007 | B8: Compliance Referral | C8: Compliance Referral — business requirement #7 | D8: Verify compliance referral scenario 7 using seeded test data | E8: User logged in with required role; seeded records visible | F8: 1. Navigate to relevant workbench 2. Locate seeded record 3. Execute action 7 4. Verify result on screen and in view | G8: Result matches business expectation and reconciles with v_lg_case_financials where applicable | I8: Not Run | J8: Medium | P8: 0
A9: CRF-008 | B9: Compliance Referral | C9: Compliance Referral — business requirement #8 | D9: Verify compliance referral scenario 8 using seeded test data | E9: User logged in with required role; seeded records visible | F9: 1. Navigate to relevant workbench 2. Locate seeded record 3. Execute action 8 4. Verify result on screen and in view | G9: Result matches business expectation and reconciles with v_lg_case_financials where applicable | I9: Not Run | J9: Medium | P9: 0
A10: CRF-009 | B10: Compliance Referral | C10: Compliance Referral — business requirement #9 | D10: Verify compliance referral scenario 9 using seeded test data | E10: User logged in with required role; seeded records visible | F10: 1. Navigate to relevant workbench 2. Locate seeded record 3. Execute action 9 4. Verify result on screen and in view | G10: Result matches business expectation and reconciles with v_lg_case_financials where applicable | I10: Not Run | J10: Low | P10: 0
A11: CRF-010 | B11: Compliance Referral | C11: Compliance Referral — business requirement #10 | D11: Verify compliance referral scenario 10 using seeded test data | E11: User logged in with required role; seeded records visible | F11: 1. Navigate to relevant workbench 2. Locate seeded record 3. Execute action 10 4. Verify result on screen and in view | G11: Result matches business expectation and reconciles with v_lg_case_financials where applicable | I11: Not Run | J11: High | P11: 0
A12: CRF-011 | B12: Compliance Referral | C12: Compliance Referral — business requirement #11 | D12: Verify compliance referral scenario 11 using seeded test data | E12: User logged in with required role; seeded records visible | F12: 1. Navigate to relevant workbench 2. Locate seeded record 3. Execute action 11 4. Verify result on screen and in view | G12: Result matches business expectation and reconciles with v_lg_case_financials where applicable | I12: Not Run | J12: High | P12: 0
A13: CRF-012 | B13: Compliance Referral | C13: Compliance Referral — business requirement #12 | D13: Verify compliance referral scenario 12 using seeded test data | E13: User logged in with required role; seeded records visible | F13: 1. Navigate to relevant workbench 2. Locate seeded record 3. Execute action 12 4. Verify result on screen and in view | G13: Result matches business expectation and reconciles with v_lg_case_financials where applicable | I13: Not Run | J13: Medium | P13: 0

Sheet 03 Benefit Referral
A1: Test ID | B1: Module | C1: Business Requirement | D1: Scenario | E1: Pre-condition | F1: Steps | G1: Expected Result | H1: Actual Result | I1: Status | J1: Priority | K1: Severity | L1: Evidence Link | M1: Tester | N1: Date | O1: Comments | P1: Pass %
A2: BRF-001 | B2: Benefit Referral | C2: Benefit Referral — business requirement #1 | D2: Verify benefit referral scenario 1 using seeded test data | E2: User logged in with required role; seeded records visible | F2: 1. Navigate to relevant workbench 2. Locate seeded record 3. Execute action 1 4. Verify result on screen and in view | G2: Result matches business expectation and reconciles with v_lg_case_financials where applicable | I2: Not Run | J2: High | P2: 0
A3: BRF-002 | B3: Benefit Referral | C3: Benefit Referral — business requirement #2 | D3: Verify benefit referral scenario 2 using seeded test data | E3: User logged in with required role; seeded records visible | F3: 1. Navigate to relevant workbench 2. Locate seeded record 3. Execute action 2 4. Verify result on screen and in view | G3: Result matches business expectation and reconciles with v_lg_case_financials where applicable | I3: Not Run | J3: Medium | P3: 0
A4: BRF-003 | B4: Benefit Referral | C4: Benefit Referral — business requirement #3 | D4: Verify benefit referral scenario 3 using seeded test data | E4: User logged in with required role; seeded records visible | F4: 1. Navigate to relevant workbench 2. Locate seeded record 3. Execute action 3 4. Verify result on screen and in view | G4: Result matches business expectation and reconciles with v_lg_case_financials where applicable | I4: Not Run | J4: Medium | P4: 0
A5: BRF-004 | B5: Benefit Referral | C5: Benefit Referral — business requirement #4 | D5: Verify benefit referral scenario 4 using seeded test data | E5: User logged in with required role; seeded records visible | F5: 1. Navigate to relevant workbench 2. Locate seeded record 3. Execute action 4 4. Verify result on screen and in view | G5: Result matches business expectation and reconciles with v_lg_case_financials where applicable | I5: Not Run | J5: Low | P5: 0

Sheet 04 Intake
A1: Test ID | B1: Module | C1: Business Requirement | D1: Scenario | E1: Pre-condition | F1: Steps | G1: Expected Result | H1: Actual Result | I1: Status | J1: Priority | K1: Severity | L1: Evidence Link | M1: Tester | N1: Date | O1: Comments | P1: Pass %
A2: INT-001 | B2: Legal Intake | C2: Legal Intake — business requirement #1 | D2: Verify legal intake scenario 1 using seeded test data | E2: User logged in with required role; seeded records visible | F2: 1. Navigate to relevant workbench 2. Locate seeded record 3. Execute action 1 4. Verify result on screen and in view | G2: Result matches business expectation and reconciles with v_lg_case_financials where applicable | I2: Not Run | J2: High | P2: 0
A3: INT-002 | B3: Legal Intake | C3: Legal Intake — business requirement #2 | D3: Verify legal intake scenario 2 using seeded test data | E3: User logged in with required role; seeded records visible | F3: 1. Navigate to relevant workbench 2. Locate seeded record 3. Execute action 2 4. Verify result on screen and in view | G3: Result matches business expectation and reconciles with v_lg_case_financials where applicable | I3: Not Run | J3: Medium | P3: 0
A4: INT-003 | B4: Legal Intake | C4: Legal Intake — business requirement #3 | D4: Verify legal intake scenario 3 using seeded test data | E4: User logged in with required role; seeded records visible | F4: 1. Navigate to relevant workbench 2. Locate seeded record 3. Execute action 3 4. Verify result on screen and in view | G4: Result matches business expectation and reconciles with v_lg_case_financials where applicable | I4: Not Run | J4: Medium | P4: 0
A5: INT-004 | B5: Legal Intake | C5: Legal Intake — business requirement #4 | D5: Verify legal intake scenario 4 using seeded test data | E5: User logged in with required role; seeded records visible | F5: 1. Navigate to relevant workbench 2. Locate seeded record 3. Execute action 4 4. Verify result on screen and in view | G5: Result matches business expectation and reconciles with v_lg_case_financials where applicable | I5: Not Run | J5: Low | P5: 0
A6: INT-005 | B6: Legal Intake | C6: Legal Intake — business requirement #5 | D6: Verify legal intake scenario 5 using seeded test data | E6: User logged in with required role; seeded records visible | F6: 1. Navigate to relevant workbench 2. Locate seeded record 3. Execute action 5 4. Verify result on screen and in view | G6: Result matches business expectation and reconciles with v_lg_case_financials where applicable | I6: Not Run | J6: High | P6: 0
A7: INT-006 | B7: Legal Intake | C7: Legal Intake — business requirement #6 | D7: Verify legal intake scenario 6 using seeded test data | E7: User logged in with required role; seeded records visible | F7: 1. Navigate to relevant workbench 2. Locate seeded record 3. Execute action 6 4. Verify result on screen and in view | G7: Result matches business expectation and reconciles with v_lg_case_financials where applicable | I7: Not Run | J7: High | P7: 0
A8: INT-007 | B8: Legal Intake | C8: Legal Intake — business requirement #7 | D8: Verify legal intake scenario 7 using seeded test data | E8: User logged in with required role; seeded records visible | F8: 1. Navigate to relevant workbench 2. Locate seeded record 3. Execute action 7 4. Verify result on screen and in view | G8: Result matches business expectation and reconciles with v_lg_case_financials where applicable | I8: Not Run | J8: Medium | P8: 0
A9: INT-008 | B9: Legal Intake | C9: Legal Intake — business requirement #8 | D9: Verify legal intake scenario 8 using seeded test data | E9: User logged in with required role; seeded records visible | F9: 1. Navigate to relevant workbench 2. Locate seeded record 3. Execute action 8 4. Verify result on screen and in view | G9: Result matches business expectation and reconciles with v_lg_case_financials where applicable | I9: Not Run | J9: Medium | P9: 0
A10: INT-009 | B10: Legal Intake | C10: Legal Intake — business requirement #9 | D10: Verify legal intake scenario 9 using seeded test data | E10: User logged in with required role; seeded records visible | F10: 1. Navigate to relevant workbench 2. Locate seeded record 3. Execute action 9 4. Verify result on screen and in view | G10: Result matches business expectation and reconciles with v_lg_case_financials where applicable | I10: Not Run | J10: Low | P10: 0
A11: INT-010 | B11: Legal Intake | C11: Legal Intake — business requirement #10 | D11: Verify legal intake scenario 10 using seeded test data | E11: User logged in with required role; seeded records visible | F11: 1. Navigate to relevant workbench 2. Locate seeded record 3. Execute action 10 4. Verify result on screen and in view | G11: Result matches business expectation and reconciles with v_lg_case_financials where applicable | I11: Not Run | J11: High | P11: 0

Sheet 05 Legal Matter
A1: Test ID | B1: Module | C1: Business Requirement | D1: Scenario | E1: Pre-condition | F1: Steps | G1: Expected Result | H1: Actual Result | I1: Status | J1: Priority | K1: Severity | L1: Evidence Link | M1: Tester | N1: Date | O1: Comments | P1: Pass %
A2: MAT-001 | B2: Matter Workspace | C2: Matter Workspace — business requirement #1 | D2: Verify matter workspace scenario 1 using seeded test data | E2: User logged in with required role; seeded records visible | F2: 1. Navigate to relevant workbench 2. Locate seeded record 3. Execute action 1 4. Verify result on screen and in view | G2: Result matches business expectation and reconciles with v_lg_case_financials where applicable | I2: Not Run | J2: High | P2: 0
A3: MAT-002 | B3: Matter Workspace | C3: Matter Workspace — business requirement #2 | D3: Verify matter workspace scenario 2 using seeded test data | E3: User logged in with required role; seeded records visible | F3: 1. Navigate to relevant workbench 2. Locate seeded record 3. Execute action 2 4. Verify result on screen and in view | G3: Result matches business expectation and reconciles with v_lg_case_financials where applicable | I3: Not Run | J3: Medium | P3: 0
A4: MAT-003 | B4: Matter Workspace | C4: Matter Workspace — business requirement #3 | D4: Verify matter workspace scenario 3 using seeded test data | E4: User logged in with required role; seeded records visible | F4: 1. Navigate to relevant workbench 2. Locate seeded record 3. Execute action 3 4. Verify result on screen and in view | G4: Result matches business expectation and reconciles with v_lg_case_financials where applicable | I4: Not Run | J4: Medium | P4: 0
A5: MAT-004 | B5: Matter Workspace | C5: Matter Workspace — business requirement #4 | D5: Verify matter workspace scenario 4 using seeded test data | E5: User logged in with required role; seeded records visible | F5: 1. Navigate to relevant workbench 2. Locate seeded record 3. Execute action 4 4. Verify result on screen and in view | G5: Result matches business expectation and reconciles with v_lg_case_financials where applicable | I5: Not Run | J5: Low | P5: 0
A6: MAT-005 | B6: Matter Workspace | C6: Matter Workspace — business requirement #5 | D6: Verify matter workspace scenario 5 using seeded test data | E6: User logged in with required role; seeded records visible | F6: 1. Navigate to relevant workbench 2. Locate seeded record 3. Execute action 5 4. Verify result on screen and in view | G6: Result matches business expectation and reconciles with v_lg_case_financials where applicable | I6: Not Run | J6: High | P6: 0
A7: MAT-006 | B7: Matter Workspace | C7: Matter Workspace — business requirement #6 | D7: Verify matter workspace scenario 6 using seeded test data | E7: User logged in with required role; seeded records visible | F7: 1. Navigate to relevant workbench 2. Locate seeded record 3. Execute action 6 4. Verify result on screen and in view | G7: Result matches business expectation and reconciles with v_lg_case_financials where applicable | I7: Not Run | J7: High | P7: 0
A8: MAT-007 | B8: Matter Workspace | C8: Matter Workspace — business requirement #7 | D8: Verify matter workspace scenario 7 using seeded test data | E8: User logged in with required role; seeded records visible | F8: 1. Navigate to relevant workbench 2. Locate seeded record 3. Execute action 7 4. Verify result on screen and in view | G8: Result matches business expectation and reconciles with v_lg_case_financials where applicable | I8: Not Run | J8: Medium | P8: 0
A9: MAT-008 | B9: Matter Workspace | C9: Matter Workspace — business requirement #8 | D9: Verify matter workspace scenario 8 using seeded test data | E9: User logged in with required role; seeded records visible | F9: 1. Navigate to relevant workbench 2. Locate seeded record 3. Execute action 8 4. Verify result on screen and in view | G9: Result matches business expectation and reconciles with v_lg_case_financials where applicable | I9: Not Run | J9: Medium | P9: 0
A10: MAT-009 | B10: Matter Workspace | C10: Matter Workspace — business requirement #9 | D10: Verify matter workspace scenario 9 using seeded test data | E10: User logged in with required role; seeded records visible | F10: 1. Navigate to relevant workbench 2. Locate seeded record 3. Execute action 9 4. Verify result on screen and in view | G10: Result matches business expectation and reconciles with v_lg_case_financials where applicable | I10: Not Run | J10: Low | P10: 0
A11: MAT-010 | B11: Matter Workspace | C11: Matter Workspace — business requirement #10 | D11: Verify matter workspace scenario 10 using seeded test data | E11: User logged in with required role; seeded records visible | F11: 1. Navigate to relevant workbench 2. Locate seeded record 3. Execute action 10 4. Verify result on screen and in view | G11: Result matches business expectation and reconciles with v_lg_case_financials where applicable | I11: Not Run | J11: High | P11: 0
A12: MAT-011 | B12: Matter Workspace | C12: Matter Workspace — business requirement #11 | D12: Verify matter workspace scenario 11 using seeded test data | E12: User logged in with required role; seeded records visible | F12: 1. Navigate to relevant workbench 2. Locate seeded record 3. Execute action 11 4. Verify result on screen and in view | G12: Result matches business expectation and reconciles with v_lg_case_financials where applicable | I12: Not Run | J12: High | P12: 0
A13: MAT-012 | B13: Matter Workspace | C13: Matter Workspace — business requirement #12 | D13: Verify matter workspace scenario 12 using seeded test data | E13: User logged in with required role; seeded records visible | F13: 1. Navigate to relevant workbench 2. Locate seeded record 3. Execute action 12 4. Verify result on screen and in view | G13: Result matches business expectation and reconciles with v_lg_case_financials where applicable | I13: Not Run | J13: Medium | P13: 0
... A15: MAT-014 | B15: Matter Workspace | C15: Matter Workspace — business requirement #14 | D15: Verify matter workspace scenario 14 using seeded test data | E15: User logged in with required role; seeded records visible | F15: 1. Navigate to relevant workbench 2. Locate seeded record 3. Execute action 14 4. Verify result on screen and in view | G15: Result matches business expectation and reconciles with v_lg_case_financials where applicable | I15: Not Run | J15: Low | P15: 0

Sheet 06 Hearings
A1: Test ID | B1: Module | C1: Business Requirement | D1: Scenario | E1: Pre-condition | F1: Steps | G1: Expected Result | H1: Actual Result | I1: Status | J1: Priority | K1: Severity | L1: Evidence Link | M1: Tester | N1: Date | O1: Comments | P1: Pass %
A2: HRG-001 | B2: Court Operations | C2: Court Operations — business requirement #1 | D2: Verify court operations scenario 1 using seeded test data | E2: User logged in with required role; seeded records visible | F2: 1. Navigate to relevant workbench 2. Locate seeded record 3. Execute action 1 4. Verify result on screen and in view | G2: Result matches business expectation and reconciles with v_lg_case_financials where applicable | I2: Not Run | J2: High | P2: 0
A3: HRG-002 | B3: Court Operations | C3: Court Operations — business requirement #2 | D3: Verify court operations scenario 2 using seeded test data | E3: User logged in with required role; seeded records visible | F3: 1. Navigate to relevant workbench 2. Locate seeded record 3. Execute action 2 4. Verify result on screen and in view | G3: Result matches business expectation and reconciles with v_lg_case_financials where applicable | I3: Not Run | J3: Medium | P3: 0
A4: HRG-003 | B4: Court Operations | C4: Court Operations — business requirement #3 | D4: Verify court operations scenario 3 using seeded test data | E4: User logged in with required role; seeded records visible | F4: 1. Navigate to relevant workbench 2. Locate seeded record 3. Execute action 3 4. Verify result on screen and in view | G4: Result matches business expectation and reconciles with v_lg_case_financials where applicable | I4: Not Run | J4: Medium | P4: 0
A5: HRG-004 | B5: Court Operations | C5: Court Operations — business requirement #4 | D5: Verify court operations scenario 4 using seeded test data | E5: User logged in with required role; seeded records visible | F5: 1. Navigate to relevant workbench 2. Locate seeded record 3. Execute action 4 4. Verify result on screen and in view | G5: Result matches business expectation and reconciles with v_lg_case_financials where applicable | I5: Not Run | J5: Low | P5: 0
A6: HRG-005 | B6: Court Operations | C6: Court Operations — business requirement #5 | D6: Verify court operations scenario 5 using seeded test data | E6: User logged in with required role; seeded records visible | F6: 1. Navigate to relevant workbench 2. Locate seeded record 3. Execute action 5 4. Verify result on screen and in view | G6: Result matches business expectation and reconciles with v_lg_case_financials where applicable | I6: Not Run | J6: High | P6: 0
A7: HRG-006 | B7: Court Operations | C7: Court Operations — business requirement #6 | D7: Verify court operations scenario 6 using seeded test data | E7: User logged in with required role; seeded records visible | F7: 1. Navigate to relevant workbench 2. Locate seeded record 3. Execute action 6 4. Verify result on screen and in view | G7: Result matches business expectation and reconciles with v_lg_case_financials where applicable | I7: Not Run | J7: High | P7: 0
A8: HRG-007 | B8: Court Operations | C8: Court Operations — business requirement #7 | D8: Verify court operations scenario 7 using seeded test data | E8: User logged in with required role; seeded records visible | F8: 1. Navigate to relevant workbench 2. Locate seeded record 3. Execute action 7 4. Verify result on screen and in view | G8: Result matches business expectation and reconciles with v_lg_case_financials where applicable | I8: Not Run | J8: Medium | P8: 0
A9: HRG-008 | B9: Court Operations | C9: Court Operations — business requirement #8 | D9: Verify court operations scenario 8 using seeded test data | E9: User logged in with required role; seeded records visible | F9: 1. Navigate to relevant workbench 2. Locate seeded record 3. Execute action 8 4. Verify result on screen and in view | G9: Result matches business expectation and reconciles with v_lg_case_financials where applicable | I9: Not Run | J9: Medium | P9: 0
A10: HRG-009 | B10: Court Operations | C10: Court Operations — business requirement #9 | D10: Verify court operations scenario 9 using seeded test data | E10: User logged in with required role; seeded records visible | F10: 1. Navigate to relevant workbench 2. Locate seeded record 3. Execute action 9 4. Verify result on screen and in view | G10: Result matches business expectation and reconciles with v_lg_case_financials where applicable | I10: Not Run | J10: Low | P10: 0
A11: HRG-010 | B11: Court Operations | C11: Court Operations — business requirement #10 | D11: Verify court operations scenario 10 using seeded test data | E11: User logged in with required role; seeded records visible | F11: 1. Navigate to relevant workbench 2. Locate seeded record 3. Execute action 10 4. Verify result on screen and in view | G11: Result matches business expectation and reconciles with v_lg_case_financials where applicable | I11: Not Run | J11: High | P11: 0

Sheet 07 Orders
A1: Test ID | B1: Module | C1: Business Requirement | D1: Scenario | E1: Pre-condition | F1: Steps | G1: Expected Result | H1: Actual Result | I1: Status | J1: Priority | K1: Severity | L1: Evidence Link | M1: Tester | N1: Date | O1: Comments | P1: Pass %
A2: ORD-001 | B2: Judicial Orders | C2: Judicial Orders — business requirement #1 | D2: Verify judicial orders scenario 1 using seeded test data | E2: User logged in with required role; seeded records visible | F2: 1. Navigate to relevant workbench 2. Locate seeded record 3. Execute action 1 4. Verify result on screen and in view | G2: Result matches business expectation and reconciles with v_lg_case_financials where applicable | I2: Not Run | J2: High | P2: 0
A3: ORD-002 | B3: Judicial Orders | C3: Judicial Orders — business requirement #2 | D3: Verify judicial orders scenario 2 using seeded test data | E3: User logged in with required role; seeded records visible | F3: 1. Navigate to relevant workbench 2. Locate seeded record 3. Execute action 2 4. Verify result on screen and in view | G3: Result matches business expectation and reconciles with v_lg_case_financials where applicable | I3: Not Run | J3: Medium | P3: 0
A4: ORD-003 | B4: Judicial Orders | C4: Judicial Orders — business requirement #3 | D4: Verify judicial orders scenario 3 using seeded test data | E4: User logged in with required role; seeded records visible | F4: 1. Navigate to relevant workbench 2. Locate seeded record 3. Execute action 3 4. Verify result on screen and in view | G4: Result matches business expectation and reconciles with v_lg_case_financials where applicable | I4: Not Run | J4: Medium | P4: 0
A5: ORD-004 | B5: Judicial Orders | C5: Judicial Orders — business requirement #4 | D5: Verify judicial orders scenario 4 using seeded test data | E5: User logged in with required role; seeded records visible | F5: 1. Navigate to relevant workbench 2. Locate seeded record 3. Execute action 4 4. Verify result on screen and in view | G5: Result matches business expectation and reconciles with v_lg_case_financials where applicable | I5: Not Run | J5: Low | P5: 0
A6: ORD-005 | B6: Judicial Orders | C6: Judicial Orders — business requirement #5 | D6: Verify judicial orders scenario 5 using seeded test data | E6: User logged in with required role; seeded records visible | F6: 1. Navigate to relevant workbench 2. Locate seeded record 3. Execute action 5 4. Verify result on screen and in view | G6: Result matches business expectation and reconciles with v_lg_case_financials where applicable | I6: Not Run | J6: High | P6: 0
A7: ORD-006 | B7: Judicial Orders | C7: Judicial Orders — business requirement #6 | D7: Verify judicial orders scenario 6 using seeded test data | E7: User logged in with required role; seeded records visible | F7: 1. Navigate to relevant workbench 2. Locate seeded record 3. Execute action 6 4. Verify result on screen and in view | G7: Result matches business expectation and reconciles with v_lg_case_financials where applicable | I7: Not Run | J7: High | P7: 0
A8: ORD-007 | B8: Judicial Orders | C8: Judicial Orders — business requirement #7 | D8: Verify judicial orders scenario 7 using seeded test data | E8: User logged in with required role; seeded records visible | F8: 1. Navigate to relevant workbench 2. Locate seeded record 3. Execute action 7 4. Verify result on screen and in view | G8: Result matches business expectation and reconciles with v_lg_case_financials where applicable | I8: Not Run | J8: Medium | P8: 0
A9: ORD-008 | B9: Judicial Orders | C9: Judicial Orders — business requirement #8 | D9: Verify judicial orders scenario 8 using seeded test data | E9: User logged in with required role; seeded records visible | F9: 1. Navigate to relevant workbench 2. Locate seeded record 3. Execute action 8 4. Verify result on screen and in view | G9: Result matches business expectation and reconciles with v_lg_case_financials where applicable | I9: Not Run | J9: Medium | P9: 0

Sheet 08 Appeals
A1: Test ID | B1: Module | C1: Business Requirement | D1: Scenario | E1: Pre-condition | F1: Steps | G1: Expected Result | H1: Actual Result | I1: Status | J1: Priority | K1: Severity | L1: Evidence Link | M1: Tester | N1: Date | O1: Comments | P1: Pass %
A2: APL-001 | B2: Appeals | C2: Appeals — business requirement #1 | D2: Verify appeals scenario 1 using seeded test data | E2: User logged in with required role; seeded records visible | F2: 1. Navigate to relevant workbench 2. Locate seeded record 3. Execute action 1 4. Verify result on screen and in view | G2: Result matches business expectation and reconciles with v_lg_case_financials where applicable | I2: Not Run | J2: High | P2: 0
A3: APL-002 | B3: Appeals | C3: Appeals — business requirement #2 | D3: Verify appeals scenario 2 using seeded test data | E3: User logged in with required role; seeded records visible | F3: 1. Navigate to relevant workbench 2. Locate seeded record 3. Execute action 2 4. Verify result on screen and in view | G3: Result matches business expectation and reconciles with v_lg_case_financials where applicable | I3: Not Run | J3: Medium | P3: 0
A4: APL-003 | B4: Appeals | C4: Appeals — business requirement #3 | D4: Verify appeals scenario 3 using seeded test data | E4: User logged in with required role; seeded records visible | F4: 1. Navigate to relevant workbench 2. Locate seeded record 3. Execute action 3 4. Verify result on screen and in view | G4: Result matches business expectation and reconciles with v_lg_case_financials where applicable | I4: Not Run | J4: Medium | P4: 0
A5: APL-004 | B5: Appeals | C5: Appeals — business requirement #4 | D5: Verify appeals scenario 4 using seeded test data | E5: User logged in with required role; seeded records visible | F5: 1. Navigate to relevant workbench 2. Locate seeded record 3. Execute action 4 4. Verify result on screen and in view | G5: Result matches business expectation and reconciles with v_lg_case_financials where applicable | I5: Not Run | J5: Low | P5: 0
A6: APL-005 | B6: Appeals | C6: Appeals — business requirement #5 | D6: Verify appeals scenario 5 using seeded test data | E6: User logged in with required role; seeded records visible | F6: 1. Navigate to relevant workbench 2. Locate seeded record 3. Execute action 5 4. Verify result on screen and in view | G6: Result matches business expectation and reconciles with v_lg_case_financials where applicable | I6: Not Run | J6: High | P6: 0
A7: APL-006 | B7: Appeals | C7: Appeals — business requirement #6 | D7: Verify appeals scenario 6 using seeded test data | E7: User logged in with required role; seeded records visible | F7: 1. Navigate to relevant workbench 2. Locate seeded record 3. Execute action 6 4. Verify result on screen and in view | G7: Result matches business expectation and reconciles with v_lg_case_financials where applicable | I7: Not Run | J7: High | P7: 0

Sheet 09 Enforcement
A1: Test ID | B1: Module | C1: Business Requirement | D1: Scenario | E1: Pre-condition | F1: Steps | G1: Expected Result | H1: Actual Result | I1: Status | J1: Priority | K1: Severity | L1: Evidence Link | M1: Tester | N1: Date | O1: Comments | P1: Pass %
A2: ENF-001 | B2: Enforcement | C2: Enforcement — business requirement #1 | D2: Verify enforcement scenario 1 using seeded test data | E2: User logged in with required role; seeded records visible | F2: 1. Navigate to relevant workbench 2. Locate seeded record 3. Execute action 1 4. Verify result on screen and in view | G2: Result matches business expectation and reconciles with v_lg_case_financials where applicable | I2: Not Run | J2: High | P2: 0
A3: ENF-002 | B3: Enforcement | C3: Enforcement — business requirement #2 | D3: Verify enforcement scenario 2 using seeded test data | E3: User logged in with required role; seeded records visible | F3: 1. Navigate to relevant workbench 2. Locate seeded record 3. Execute action 2 4. Verify result on screen and in view | G3: Result matches business expectation and reconciles with v_lg_case_financials where applicable | I3: Not Run | J3: Medium | P3: 0
A4: ENF-003 | B4: Enforcement | C4: Enforcement — business requirement #3 | D4: Verify enforcement scenario 3 using seeded test data | E4: User logged in with required role; seeded records visible | F4: 1. Navigate to relevant workbench 2. Locate seeded record 3. Execute action 3 4. Verify result on screen and in view | G4: Result matches business expectation and reconciles with v_lg_case_financials where applicable | I4: Not Run | J4: Medium | P4: 0
A5: ENF-004 | B5: Enforcement | C5: Enforcement — business requirement #4 | D5: Verify enforcement scenario 4 using seeded test data | E5: User logged in with required role; seeded records visible | F5: 1. Navigate to relevant workbench 2. Locate seeded record 3. Execute action 4 4. Verify result on screen and in view | G5: Result matches business expectation and reconciles with v_lg_case_financials where applicable | I5: Not Run | J5: Low | P5: 0
A6: ENF-005 | B6: Enforcement | C6: Enforcement — business requirement #5 | D6: Verify enforcement scenario 5 using seeded test data | E6: User logged in with required role; seeded records visible | F6: 1. Navigate to relevant workbench 2. Locate seeded record 3. Execute action 5 4. Verify result on screen and in view | G6: Result matches business expectation and reconciles with v_lg_case_financials where applicable | I6: Not Run | J6: High | P6: 0
A7: ENF-006 | B7: Enforcement | C7: Enforcement — business requirement #6 | D7: Verify enforcement scenario 6 using seeded test data | E7: User logged in with required role; seeded records visible | F7: 1. Navigate to relevant workbench 2. Locate seeded record 3. Execute action 6 4. Verify result on screen and in view | G7: Result matches business expectation and reconciles with v_lg_case_financials where applicable | I7: Not Run | J7: High | P7: 0
A8: ENF-007 | B8: Enforcement | C8: Enforcement — business requirement #7 | D8: Verify enforcement scenario 7 using seeded test data | E8: User logged in with required role; seeded records visible | F8: 1. Navigate to relevant workbench 2. Locate seeded record 3. Execute action 7 4. Verify result on screen and in view | G8: Result matches business expectation and reconciles with v_lg_case_financials where applicable | I8: Not Run | J8: Medium | P8: 0
A9: ENF-008 | B9: Enforcement | C9: Enforcement — business requirement #8 | D9: Verify enforcement scenario 8 using seeded test data | E9: User logged in with required role; seeded records visible | F9: 1. Navigate to relevant workbench 2. Locate seeded record 3. Execute action 8 4. Verify result on screen and in view | G9: Result matches business expectation and reconciles with v_lg_case_financials where applicable | I9: Not Run | J9: Medium | P9: 0

Sheet 10 Consent Orders
A1: Test ID | B1: Module | C1: Business Requirement | D1: Scenario | E1: Pre-condition | F1: Steps | G1: Expected Result | H1: Actual Result | I1: Status | J1: Priority | K1: Severity | L1: Evidence Link | M1: Tester | N1: Date | O1: Comments | P1: Pass %
A2: CON-001 | B2: Consent Orders | C2: Consent Orders — business requirement #1 | D2: Verify consent orders scenario 1 using seeded test data | E2: User logged in with required role; seeded records visible | F2: 1. Navigate to relevant workbench 2. Locate seeded record 3. Execute action 1 4. Verify result on screen and in view | G2: Result matches business expectation and reconciles with v_lg_case_financials where applicable | I2: Not Run | J2: High | P2: 0
A3: CON-002 | B3: Consent Orders | C3: Consent Orders — business requirement #2 | D3: Verify consent orders scenario 2 using seeded test data | E3: User logged in with required role; seeded records visible | F3: 1. Navigate to relevant workbench 2. Locate seeded record 3. Execute action 2 4. Verify result on screen and in view | G3: Result matches business expectation and reconciles with v_lg_case_financials where applicable | I3: Not Run | J3: Medium | P3: 0
A4: CON-003 | B4: Consent Orders | C4: Consent Orders — business requirement #3 | D4: Verify consent orders scenario 3 using seeded test data | E4: User logged in with required role; seeded records visible | F4: 1. Navigate to relevant workbench 2. Locate seeded record 3. Execute action 3 4. Verify result on screen and in view | G4: Result matches business expectation and reconciles with v_lg_case_financials where applicable | I4: Not Run | J4: Medium | P4: 0
A5: CON-004 | B5: Consent Orders | C5: Consent Orders — business requirement #4 | D5: Verify consent orders scenario 4 using seeded test data | E5: User logged in with required role; seeded records visible | F5: 1. Navigate to relevant workbench 2. Locate seeded record 3. Execute action 4 4. Verify result on screen and in view | G5: Result matches business expectation and reconciles with v_lg_case_financials where applicable | I5: Not Run | J5: Low | P5: 0
A6: CON-005 | B6: Consent Orders | C6: Consent Orders — business requirement #5 | D6: Verify consent orders scenario 5 using seeded test data | E6: User logged in with required role; seeded records visible | F6: 1. Navigate to relevant workbench 2. Locate seeded record 3. Execute action 5 4. Verify result on screen and in view | G6: Result matches business expectation and reconciles with v_lg_case_financials where applicable | I6: Not Run | J6: High | P6: 0
A7: CON-006 | B7: Consent Orders | C7: Consent Orders — business requirement #6 | D7: Verify consent orders scenario 6 using seeded test data | E7: User logged in with required role; seeded records visible | F7: 1. Navigate to relevant workbench 2. Locate seeded record 3. Execute action 6 4. Verify result on screen and in view | G7: Result matches business expectation and reconciles with v_lg_case_financials where applicable | I7: Not Run | J7: High | P7: 0

Sheet 11 Recovery Assignment
A1: Test ID | B1: Module | C1: Business Requirement | D1: Scenario | E1: Pre-condition | F1: Steps | G1: Expected Result | H1: Actual Result | I1: Status | J1: Priority | K1: Severity | L1: Evidence Link | M1: Tester | N1: Date | O1: Comments | P1: Pass %
A2: RAS-001 | B2: Recovery Assignment | C2: Recovery Assignment — business requirement #1 | D2: Verify recovery assignment scenario 1 using seeded test data | E2: User logged in with required role; seeded records visible | F2: 1. Navigate to relevant workbench 2. Locate seeded record 3. Execute action 1 4. Verify result on screen and in view | G2: Result matches business expectation and reconciles with v_lg_case_financials where applicable | I2: Not Run | J2: High | P2: 0
A3: RAS-002 | B3: Recovery Assignment | C3: Recovery Assignment — business requirement #2 | D3: Verify recovery assignment scenario 2 using seeded test data | E3: User logged in with required role; seeded records visible | F3: 1. Navigate to relevant workbench 2. Locate seeded record 3. Execute action 2 4. Verify result on screen and in view | G3: Result matches business expectation and reconciles with v_lg_case_financials where applicable | I3: Not Run | J3: Medium | P3: 0
A4: RAS-003 | B4: Recovery Assignment | C4: Recovery Assignment — business requirement #3 | D4: Verify recovery assignment scenario 3 using seeded test data | E4: User logged in with required role; seeded records visible | F4: 1. Navigate to relevant workbench 2. Locate seeded record 3. Execute action 3 4. Verify result on screen and in view | G4: Result matches business expectation and reconciles with v_lg_case_financials where applicable | I4: Not Run | J4: Medium | P4: 0
A5: RAS-004 | B5: Recovery Assignment | C5: Recovery Assignment — business requirement #4 | D5: Verify recovery assignment scenario 4 using seeded test data | E5: User logged in with required role; seeded records visible | F5: 1. Navigate to relevant workbench 2. Locate seeded record 3. Execute action 4 4. Verify result on screen and in view | G5: Result matches business expectation and reconciles with v_lg_case_financials where applicable | I5: Not Run | J5: Low | P5: 0
A6: RAS-005 | B6: Recovery Assignment | C6: Recovery Assignment — business requirement #5 | D6: Verify recovery assignment scenario 5 using seeded test data | E6: User logged in with required role; seeded records visible | F6: 1. Navigate to relevant workbench 2. Locate seeded record 3. Execute action 5 4. Verify result on screen and in view | G6: Result matches business expectation and reconciles with v_lg_case_financials where applicable | I6: Not Run | J6: High | P6: 0
A7: RAS-006 | B7: Recovery Assignment | C7: Recovery Assignment — business requirement #6 | D7: Verify recovery assignment scenario 6 using seeded test data | E7: User logged in with required role; seeded records visible | F7: 1. Navigate to relevant workbench 2. Locate seeded record 3. Execute action 6 4. Verify result on screen and in view | G7: Result matches business expectation and reconciles with v_lg_case_financials where applicable | I7: Not Run | J7: High | P7: 0
A8: RAS-007 | B8: Recovery Assignment | C8: Recovery Assignment — business requirement #7 | D8: Verify recovery assignment scenario 7 using seeded test data | E8: User logged in with required role; seeded records visible | F8: 1. Navigate to relevant workbench 2. Locate seeded record 3. Execute action 7 4. Verify result on screen and in view | G8: Result matches business expectation and reconciles with v_lg_case_financials where applicable | I8: Not Run | J8: Medium | P8: 0
A9: RAS-008 | B9: Recovery Assignment | C9: Recovery Assignment — business requirement #8 | D9: Verify recovery assignment scenario 8 using seeded test data | E9: User logged in with required role; seeded records visible | F9: 1. Navigate to relevant workbench 2. Locate seeded record 3. Execute action 8 4. Verify result on screen and in view | G9: Result matches business expectation and reconciles with v_lg_case_financials where applicable | I9: Not Run | J9: Medium | P9: 0

Sheet 12 Recoverable Liabilities
A1: Test ID | B1: Module | C1: Business Requirement | D1: Scenario | E1: Pre-condition | F1: Steps | G1: Expected Result | H1: Actual Result | I1: Status | J1: Priority | K1: Severity | L1: Evidence Link | M1: Tester | N1: Date | O1: Comments | P1: Pass %
A2: LIA-001 | B2: Liabilities | C2: Liabilities — business requirement #1 | D2: Verify liabilities scenario 1 using seeded test data | E2: User logged in with required role; seeded records visible | F2: 1. Navigate to relevant workbench 2. Locate seeded record 3. Execute action 1 4. Verify result on screen and in view | G2: Result matches business expectation and reconciles with v_lg_case_financials where applicable | I2: Not Run | J2: High | P2: 0
A3: LIA-002 | B3: Liabilities | C3: Liabilities — business requirement #2 | D3: Verify liabilities scenario 2 using seeded test data | E3: User logged in with required role; seeded records visible | F3: 1. Navigate to relevant workbench 2. Locate seeded record 3. Execute action 2 4. Verify result on screen and in view | G3: Result matches business expectation and reconciles with v_lg_case_financials where applicable | I3: Not Run | J3: Medium | P3: 0
A4: LIA-003 | B4: Liabilities | C4: Liabilities — business requirement #3 | D4: Verify liabilities scenario 3 using seeded test data | E4: User logged in with required role; seeded records visible | F4: 1. Navigate to relevant workbench 2. Locate seeded record 3. Execute action 3 4. Verify result on screen and in view | G4: Result matches business expectation and reconciles with v_lg_case_financials where applicable | I4: Not Run | J4: Medium | P4: 0
A5: LIA-004 | B5: Liabilities | C5: Liabilities — business requirement #4 | D5: Verify liabilities scenario 4 using seeded test data | E5: User logged in with required role; seeded records visible | F5: 1. Navigate to relevant workbench 2. Locate seeded record 3. Execute action 4 4. Verify result on screen and in view | G5: Result matches business expectation and reconciles with v_lg_case_financials where applicable | I5: Not Run | J5: Low | P5: 0
A6: LIA-005 | B6: Liabilities | C6: Liabilities — business requirement #5 | D6: Verify liabilities scenario 5 using seeded test data | E6: User logged in with required role; seeded records visible | F6: 1. Navigate to relevant workbench 2. Locate seeded record 3. Execute action 5 4. Verify result on screen and in view | G6: Result matches business expectation and reconciles with v_lg_case_financials where applicable | I6: Not Run | J6: High | P6: 0
A7: LIA-006 | B7: Liabilities | C7: Liabilities — business requirement #6 | D7: Verify liabilities scenario 6 using seeded test data | E7: User logged in with required role; seeded records visible | F7: 1. Navigate to relevant workbench 2. Locate seeded record 3. Execute action 6 4. Verify result on screen and in view | G7: Result matches business expectation and reconciles with v_lg_case_financials where applicable | I7: Not Run | J7: High | P7: 0
A8: LIA-007 | B8: Liabilities | C8: Liabilities — business requirement #7 | D8: Verify liabilities scenario 7 using seeded test data | E8: User logged in with required role; seeded records visible | F8: 1. Navigate to relevant workbench 2. Locate seeded record 3. Execute action 7 4. Verify result on screen and in view | G8: Result matches business expectation and reconciles with v_lg_case_financials where applicable | I8: Not Run | J8: Medium | P8: 0
A9: LIA-008 | B9: Liabilities | C9: Liabilities — business requirement #8 | D9: Verify liabilities scenario 8 using seeded test data | E9: User logged in with required role; seeded records visible | F9: 1. Navigate to relevant workbench 2. Locate seeded record 3. Execute action 8 4. Verify result on screen and in view | G9: Result matches business expectation and reconciles with v_lg_case_financials where applicable | I9: Not Run | J9: Medium | P9: 0
A10: LIA-009 | B10: Liabilities | C10: Liabilities — business requirement #9 | D10: Verify liabilities scenario 9 using seeded test data | E10: User logged in with required role; seeded records visible | F10: 1. Navigate to relevant workbench 2. Locate seeded record 3. Execute action 9 4. Verify result on screen and in view | G10: Result matches business expectation and reconciles with v_lg_case_financials where applicable | I10: Not Run | J10: Low | P10: 0
A11: LIA-010 | B11: Liabilities | C11: Liabilities — business requirement #10 | D11: Verify liabilities scenario 10 using seeded test data | E11: User logged in with required role; seeded records visible | F11: 1. Navigate to relevant workbench 2. Locate seeded record 3. Execute action 10 4. Verify result on screen and in view | G11: Result matches business expectation and reconciles with v_lg_case_financials where applicable | I11: Not Run | J11: High | P11: 0
A12: LIA-011 | B12: Liabilities | C12: Liabilities — business requirement #11 | D12: Verify liabilities scenario 11 using seeded test data | E12: User logged in with required role; seeded records visible | F12: 1. Navigate to relevant workbench 2. Locate seeded record 3. Execute action 11 4. Verify result on screen and in view | G12: Result matches business expectation and reconciles with v_lg_case_financials where applicable | I12: Not Run | J12: High | P12: 0
A13: LIA-012 | B13: Liabilities | C13: Liabilities — business requirement #12 | D13: Verify liabilities scenario 12 using seeded test data | E13: User logged in with required role; seeded records visible | F13: 1. Navigate to relevant workbench 2. Locate seeded record 3. Execute action 12 4. Verify result on screen and in view | G13: Result matches business expectation and reconciles with v_lg_case_financials where applicable | I13: Not Run | J13: Medium | P13: 0

Sheet 13 External Counsel
A1: Test ID | B1: Module | C1: Business Requirement | D1: Scenario | E1: Pre-condition | F1: Steps | G1: Expected Result | H1: Actual Result | I1: Status | J1: Priority | K1: Severity | L1: Evidence Link | M1: Tester | N1: Date | O1: Comments | P1: Pass %
A2: ECL-001 | B2: External Counsel | C2: External Counsel — business requirement #1 | D2: Verify external counsel scenario 1 using seeded test data | E2: User logged in with required role; seeded records visible | F2: 1. Navigate to relevant workbench 2. Locate seeded record 3. Execute action 1 4. Verify result on screen and in view | G2: Result matches business expectation and reconciles with v_lg_case_financials where applicable | I2: Not Run | J2: High | P2: 0
A3: ECL-002 | B3: External Counsel | C3: External Counsel — business requirement #2 | D3: Verify external counsel scenario 2 using seeded test data | E3: User logged in with required role; seeded records visible | F3: 1. Navigate to relevant workbench 2. Locate seeded record 3. Execute action 2 4. Verify result on screen and in view | G3: Result matches business expectation and reconciles with v_lg_case_financials where applicable | I3: Not Run | J3: Medium | P3: 0
A4: ECL-003 | B4: External Counsel | C4: External Counsel — business requirement #3 | D4: Verify external counsel scenario 3 using seeded test data | E4: User logged in with required role; seeded records visible | F4: 1. Navigate to relevant workbench 2. Locate seeded record 3. Execute action 3 4. Verify result on screen and in view | G4: Result matches business expectation and reconciles with v_lg_case_financials where applicable | I4: Not Run | J4: Medium | P4: 0
A5: ECL-004 | B5: External Counsel | C5: External Counsel — business requirement #4 | D5: Verify external counsel scenario 4 using seeded test data | E5: User logged in with required role; seeded records visible | F5: 1. Navigate to relevant workbench 2. Locate seeded record 3. Execute action 4 4. Verify result on screen and in view | G5: Result matches business expectation and reconciles with v_lg_case_financials where applicable | I5: Not Run | J5: Low | P5: 0
A6: ECL-005 | B6: External Counsel | C6: External Counsel — business requirement #5 | D6: Verify external counsel scenario 5 using seeded test data | E6: User logged in with required role; seeded records visible | F6: 1. Navigate to relevant workbench 2. Locate seeded record 3. Execute action 5 4. Verify result on screen and in view | G6: Result matches business expectation and reconciles with v_lg_case_financials where applicable | I6: Not Run | J6: High | P6: 0

Sheet 14 Court Filing
